[2024-02-28T02:52:11.776+0000] {taskinstance.py:1979} INFO - Dependencies all met for dep_context=non-requeueable deps ti=<TaskInstance: copy_to_mongodb.load_to_mongodb manual__2024-02-28T02:37:05.240141+00:00 [queued]>
[2024-02-28T02:52:11.787+0000] {taskinstance.py:1979} INFO - Dependencies all met for dep_context=requeueable deps ti=<TaskInstance: copy_to_mongodb.load_to_mongodb manual__2024-02-28T02:37:05.240141+00:00 [queued]>
[2024-02-28T02:52:11.788+0000] {taskinstance.py:2193} INFO - Starting attempt 2 of 2
[2024-02-28T02:52:11.809+0000] {taskinstance.py:2214} INFO - Executing <Task(PythonOperator): load_to_mongodb> on 2024-02-28 02:37:05.240141+00:00
[2024-02-28T02:52:11.819+0000] {standard_task_runner.py:60} INFO - Started process 455 to run task
[2024-02-28T02:52:11.823+0000] {standard_task_runner.py:87} INFO - Running: ['***', 'tasks', 'run', 'copy_to_mongodb', 'load_to_mongodb', 'manual__2024-02-28T02:37:05.240141+00:00', '--job-id', '6', '--raw', '--subdir', 'DAGS_FOLDER/main.py', '--cfg-path', '/tmp/tmp8dorygjx']
[2024-02-28T02:52:11.828+0000] {standard_task_runner.py:88} INFO - Job 6: Subtask load_to_mongodb
[2024-02-28T02:52:11.844+0000] {logging_mixin.py:188} WARNING - /home/***/.local/lib/python3.11/site-packages/***/settings.py:194 DeprecationWarning: The sql_alchemy_conn option in [core] has been moved to the sql_alchemy_conn option in [database] - the old setting has been used, but please update your config.
[2024-02-28T02:52:11.891+0000] {task_command.py:423} INFO - Running <TaskInstance: copy_to_mongodb.load_to_mongodb manual__2024-02-28T02:37:05.240141+00:00 [running]> on host 9e353f13eb48
[2024-02-28T02:52:11.973+0000] {taskinstance.py:2510} INFO - Exporting env vars: AIRFLOW_CTX_DAG_OWNER='***' AIRFLOW_CTX_DAG_ID='copy_to_mongodb' AIRFLOW_CTX_TASK_ID='load_to_mongodb' AIRFLOW_CTX_EXECUTION_DATE='2024-02-28T02:37:05.240141+00:00' AIRFLOW_CTX_TRY_NUMBER='2' AIRFLOW_CTX_DAG_RUN_ID='manual__2024-02-28T02:37:05.240141+00:00'
[2024-02-28T02:52:11.998+0000] {taskinstance.py:2728} ERROR - Task failed with exception
Traceback (most recent call last):
  File "/home/airflow/.local/lib/python3.11/site-packages/airflow/models/taskinstance.py", line 444, in _execute_task
    result = _execute_callable(context=context, **execute_callable_kwargs)
             ^^^^^^^^^^^^^^^^^^^^^^^^^^^^^^^^^^^^^^^^^^^^^^^^^^^^^^^^^^^^^
  File "/home/airflow/.local/lib/python3.11/site-packages/airflow/models/taskinstance.py", line 414, in _execute_callable
    return execute_callable(context=context, **execute_callable_kwargs)
           ^^^^^^^^^^^^^^^^^^^^^^^^^^^^^^^^^^^^^^^^^^^^^^^^^^^^^^^^^^^^
  File "/home/airflow/.local/lib/python3.11/site-packages/airflow/operators/python.py", line 200, in execute
    return_value = self.execute_callable()
                   ^^^^^^^^^^^^^^^^^^^^^^^
  File "/home/airflow/.local/lib/python3.11/site-packages/airflow/operators/python.py", line 217, in execute_callable
    return self.python_callable(*self.op_args, **self.op_kwargs)
           ^^^^^^^^^^^^^^^^^^^^^^^^^^^^^^^^^^^^^^^^^^^^^^^^^^^^^
  File "/opt/airflow/dags/main.py", line 18, in load_to_mongodb
    mongo_hook = MongoHook(mongo_conn_id)
                 ^^^^^^^^^^^^^^^^^^^^^^^^
  File "/home/airflow/.local/lib/python3.11/site-packages/airflow/providers/mongo/hooks/mongo.py", line 94, in __init__
    self.connection = self.get_connection(self.mongo_conn_id)
                      ^^^^^^^^^^^^^^^^^^^^^^^^^^^^^^^^^^^^^^^
  File "/home/airflow/.local/lib/python3.11/site-packages/airflow/hooks/base.py", line 82, in get_connection
    conn = Connection.get_connection_from_secrets(conn_id)
           ^^^^^^^^^^^^^^^^^^^^^^^^^^^^^^^^^^^^^^^^^^^^^^^
  File "/home/airflow/.local/lib/python3.11/site-packages/airflow/models/connection.py", line 514, in get_connection_from_secrets
    raise AirflowNotFoundException(f"The conn_id `{conn_id}` isn't defined")
airflow.exceptions.AirflowNotFoundException: The conn_id `your_mongo_connection_id` isn't defined
[2024-02-28T02:52:12.005+0000] {taskinstance.py:1149} INFO - Marking task as FAILED. dag_id=copy_to_mongodb, task_id=load_to_mongodb, execution_date=20240228T023705, start_date=20240228T025211, end_date=20240228T025212
[2024-02-28T02:52:12.020+0000] {standard_task_runner.py:107} ERROR - Failed to execute job 6 for task load_to_mongodb (The conn_id `your_mongo_connection_id` isn't defined; 455)
[2024-02-28T02:52:12.045+0000] {local_task_job_runner.py:234} INFO - Task exited with return code 1
[2024-02-28T02:52:12.088+0000] {taskinstance.py:3309} INFO - 0 downstream tasks scheduled from follow-on schedule check
